<?xml version="1.0" encoding="utf-8"?>
<!-- This URDF was automatically created by SolidWorks to URDF Exporter! Originally created by Stephen Brawner (brawner@gmail.com) 
     Commit Version: 1.6.0-4-g7f85cfe  Build Version: 1.6.7995.38578
     For more information, please see http://wiki.ros.org/sw_urdf_exporter -->
<robot
  name="delta">
  <link
    name="base_link">
    <inertial>
      <origin
        xyz="-3.93735930499517E-05 -6.53090112989752E-07 0.00150000000000006"
        rpy="0 0 0" />
      <mass
        value="0.348053922322763" />
      <inertia
        ixx="0.00331289541444259"
        ixy="-4.5944954583715E-08"
        ixz="5.32360008035065E-21"
        iyy="0.00330737440416685"
        iyz="-2.73261647182076E-21"
        izz="0.00661974773772595" />
    </inertial>
    <visual>
      <origin
        xyz="0 0 0"
        rpy="0 0 0" />
      <geometry>
        <mesh
          filename="package://delta/meshes/base_link.STL" />
      </geometry>
      <material
        name="">
        <color
          rgba="0.792156862745098 0.819607843137255 0.933333333333333 1" />
      </material>
    </visual>
    <collision>
      <origin
        xyz="0 0 0"
        rpy="0 0 0" />
      <geometry>
        <mesh
          filename="package://delta/meshes/base_link.STL" />
      </geometry>
    </collision>
  </link>
  <link
    name="Biceb1">
    <inertial>
      <origin
        xyz="-0.00175219449537356 0.140948034908345 -1.55431223447522E-14"
        rpy="0 0 0" />
      <mass
        value="0.0192073729616364" />
      <inertia
        ixx="0.000166344843633276"
        ixy="-5.78476030023068E-19"
        ixz="7.36554421223031E-21"
        iyy="1.42950996298081E-06"
        iyz="-3.36272080059957E-19"
        izz="0.000164928138585603" />
    </inertial>
    <visual>
      <origin
        xyz="0 0 0"
        rpy="0 0 0" />
      <geometry>
        <mesh
          filename="package://delta/meshes/Biceb1.STL" />
      </geometry>
      <material
        name="">
        <color
          rgba="0.792156862745098 0.819607843137255 0.933333333333333 1" />
      </material>
    </visual>
    <collision>
      <origin
        xyz="0 0 0"
        rpy="0 0 0" />
      <geometry>
        <mesh
          filename="package://delta/meshes/Biceb1.STL" />
      </geometry>
    </collision>
  </link>
  <joint
    name="biceb_base1"
    type="continuous">
    <origin
      xyz="-0.0832594172832655 0.137739428572839 -0.0340056335963721"
      rpy="2.61864428276593 0 -2.62049388059565" />
    <parent
      link="base_link" />
    <child
      link="Biceb1" />
    <axis
      xyz="1 0 0" />
  </joint>
  <link
    name="con11">
    <inertial>
      <origin
        xyz="-2.22044604925031E-16 -4.58855176077577E-13 -1.26032517755448E-12"
        rpy="0 0 0" />
      <mass
        value="0.00746291618045562" />
      <inertia
        ixx="2.35119174265254E-07"
        ixy="7.86197529672799E-22"
        ixz="9.87288690597737E-22"
        iyy="4.75779563794496E-07"
        iyz="1.98523347012727E-23"
        izz="4.75779563794496E-07" />
    </inertial>
    <visual>
      <origin
        xyz="0 0 0"
        rpy="0 0 0" />
      <geometry>
        <mesh
          filename="package://delta/meshes/con11.STL" />
      </geometry>
      <material
        name="">
        <color
          rgba="0.792156862745098 0.819607843137255 0.933333333333333 1" />
      </material>
    </visual>
    <collision>
      <origin
        xyz="0 0 0"
        rpy="0 0 0" />
      <geometry>
        <mesh
          filename="package://delta/meshes/con11.STL" />
      </geometry>
    </collision>
  </link>
  <joint
    name="biceb_con11"
    type="continuous">
    <origin
      xyz="-0.00175219449537278 0.290000000000432 0"
      rpy="-2.52011841883488 0 0" />
    <parent
      link="Biceb1" />
    <child
      link="con11" />
    <axis
      xyz="1 0 0" />
  </joint>
  <link
    name="forarm1">
    <inertial>
      <origin
        xyz="-0.00105037351656745 0.12751236646494 -0.22343253661117"
        rpy="0 0 0" />
      <mass
        value="0.0144304095608038" />
      <inertia
        ixx="0.000353658949999369"
        ixy="7.15854739250017E-07"
        ixz="-1.25364970198116E-06"
        iyy="0.000266784814617863"
        iyz="0.000152202286062711"
        izz="8.69510919608883E-05" />
    </inertial>
    <visual>
      <origin
        xyz="0 0 0"
        rpy="0 0 0" />
      <geometry>
        <mesh
          filename="package://delta/meshes/forarm1.STL" />
      </geometry>
      <material
        name="">
        <color
          rgba="0.792156862745098 0.819607843137255 0.933333333333333 1" />
      </material>
    </visual>
    <collision>
      <origin
        xyz="0 0 0"
        rpy="0 0 0" />
      <geometry>
        <mesh
          filename="package://delta/meshes/forarm1.STL" />
      </geometry>
    </collision>
  </link>
  <joint
    name="forarm1_con11"
    type="continuous">
    <origin
      xyz="-0.0290000000000009 0 0"
      rpy="0 0 0" />
    <parent
      link="con11" />
    <child
      link="forarm1" />
    <axis
      xyz="0 -1 0" />
  </joint>
  <link
    name="con21">
    <inertial>
      <origin
        xyz="-1.75326420048805E-12 -0.0100000000102225 0.00993633272145739"
        rpy="0 0 0" />
      <mass
        value="0.0809173532040043" />
      <inertia
        ixx="5.75744317100171E-05"
        ixy="7.04096137405137E-20"
        ixz="8.70425313479776E-21"
        iyy="5.7574431710017E-05"
        iyz="1.39854079431504E-20"
        izz="0.000110342088917036" />
    </inertial>
    <visual>
      <origin
        xyz="0 0 0"
        rpy="0 0 0" />
      <geometry>
        <mesh
          filename="package://delta/meshes/con21.STL" />
      </geometry>
      <material
        name="">
        <color
          rgba="0.792156862745098 0.819607843137255 0.933333333333333 1" />
      </material>
    </visual>
    <collision>
      <origin
        xyz="0 0 0"
        rpy="0 0 0" />
      <geometry>
        <mesh
          filename="package://delta/meshes/con21.STL" />
      </geometry>
    </collision>
  </link>
  <joint
    name="lowerforarm_con21"
    type="fixed">
    <origin
      xyz="0.0164440772855872 0.359054564084232 -0.558556636293173"
      rpy="0 0.0985258639310481 1.57079632679488" />
    <parent
      link="forarm1" />
    <child
      link="con21" />
    <axis
      xyz="0 0 0" />
  </joint>
  <link
    name="forarm2">
    <inertial>
      <origin
        xyz="-0.00105037385122753 0.127512281223115 -0.223432387592727"
        rpy="0 0 0" />
      <mass
        value="0.0144304199499565" />
      <inertia
        ixx="0.000353658956230085"
        ixy="7.15436472505439E-07"
        ixz="-1.25388843231636E-06"
        iyy="0.00026678480927425"
        iyz="0.000152202284855621"
        izz="8.69510923658863E-05" />
    </inertial>
    <visual>
      <origin
        xyz="0 0 0"
        rpy="0 0 0" />
      <geometry>
        <mesh
          filename="package://delta/meshes/forarm2.STL" />
      </geometry>
      <material
        name="">
        <color
          rgba="0.792156862745098 0.819607843137255 0.933333333333333 1" />
      </material>
    </visual>
    <collision>
      <origin
        xyz="0 0 0"
        rpy="0 0 0" />
      <geometry>
        <mesh
          filename="package://delta/meshes/forarm2.STL" />
      </geometry>
    </collision>
  </link>
  <joint
    name="forarm2_con11"
    type="continuous">
    <origin
      xyz="0.0290000000000059 0 0"
      rpy="0 0 0" />
    <parent
      link="con11" />
    <child
      link="forarm2" />
    <axis
      xyz="0 -1 0" />
  </joint>
  <link
    name="Biceb2">
    <inertial>
      <origin
        xyz="-0.000793548812675793 0.150948034908535 -4.44089209850063E-16"
        rpy="0 0 0" />
      <mass
        value="0.0192073729616366" />
      <inertia
        ixx="0.000166344843633275"
        ixy="-5.94365559867612E-19"
        ixz="1.43922884424633E-20"
        iyy="1.42950996298083E-06"
        iyz="1.82217962778081E-19"
        izz="0.000164928138585602" />
    </inertial>
    <visual>
      <origin
        xyz="0 0 0"
        rpy="0 0 0" />
      <geometry>
        <mesh
          filename="package://delta/meshes/Biceb2.STL" />
      </geometry>
      <material
        name="">
        <color
          rgba="0.792156862745098 0.819607843137255 0.933333333333333 1" />
      </material>
    </visual>
    <collision>
      <origin
        xyz="0 0 0"
        rpy="0 0 0" />
      <geometry>
        <mesh
          filename="package://delta/meshes/Biceb2.STL" />
      </geometry>
    </collision>
  </link>
  <joint
    name="biceb_base2"
    type="continuous">
    <origin
      xyz="-0.0764517616066354 -0.131657111631686 -0.0389999999999996"
      rpy="2.6205547388268 0 -0.52609877820246" />
    <parent
      link="base_link" />
    <child
      link="Biceb2" />
    <axis
      xyz="1 0 0" />
  </joint>
  <link
    name="con12">
    <inertial>
      <origin
        xyz="-1.28563826251593E-13 8.84489148589296E-11 1.53866919205825E-10"
        rpy="0 0 0" />
      <mass
        value="0.00746291618045565" />
      <inertia
        ixx="2.35119684360029E-07"
        ixy="-3.5037029932656E-10"
        ixz="2.01341770111172E-23"
        iyy="4.75779053699729E-07"
        iyz="2.06464519551821E-24"
        izz="4.75779563794502E-07" />
    </inertial>
    <visual>
      <origin
        xyz="0 0 0"
        rpy="0 0 0" />
      <geometry>
        <mesh
          filename="package://delta/meshes/con12.STL" />
      </geometry>
      <material
        name="">
        <color
          rgba="0.792156862745098 0.819607843137255 0.933333333333333 1" />
      </material>
    </visual>
    <collision>
      <origin
        xyz="0 0 0"
        rpy="0 0 0" />
      <geometry>
        <mesh
          filename="package://delta/meshes/con12.STL" />
      </geometry>
    </collision>
  </link>
  <joint
    name="biceb_con12"
    type="continuous">
    <origin
      xyz="-0.000793548812675571 0.30000000000012 0"
      rpy="-2.62055519636295 -0.000724704782518244 0.0012626826229493" />
    <parent
      link="Biceb2" />
    <child
      link="con12" />
    <axis
      xyz="0.999998940218113 0.00145587178400935 0" />
  </joint>
  <link
    name="forarm3">
    <inertial>
      <origin
        xyz="0.000285220430548572 0.149163028038896 -0.209601804943243"
        rpy="0 0 0" />
      <mass
        value="0.0144304093668612" />
      <inertia
        ixx="0.000353650598470555"
        ixy="-2.33871923199319E-07"
        ixz="3.14651310226804E-07"
        iyy="0.000234793001946604"
        iyz="0.000167030407797497"
        izz="0.000118951256167155" />
    </inertial>
    <visual>
      <origin
        xyz="0 0 0"
        rpy="0 0 0" />
      <geometry>
        <mesh
          filename="package://delta/meshes/forarm3.STL" />
      </geometry>
      <material
        name="">
        <color
          rgba="0.752941176470588 0.752941176470588 0.752941176470588 1" />
      </material>
    </visual>
    <collision>
      <origin
        xyz="0 0 0"
        rpy="0 0 0" />
      <geometry>
        <mesh
          filename="package://delta/meshes/forarm3.STL" />
      </geometry>
    </collision>
  </link>
  <joint
    name="forarm3_con12"
    type="continuous">
    <origin
      xyz="-0.0289999692664815 -4.22202818657347E-05 0"
      rpy="0 0 0" />
    <parent
      link="con12" />
    <child
      link="forarm3" />
    <axis
      xyz="0 1 0" />
  </joint>
  <link
    name="forarm4">
    <inertial>
      <origin
        xyz="0.000285212092565823 0.149163030494388 -0.209601798243019"
        rpy="0 0 0" />
      <mass
        value="0.0144304096228618" />
      <inertia
        ixx="0.000353658433414418"
        ixy="-2.3434286089199E-07"
        ixz="3.14325935369369E-07"
        iyy="0.00023478780280554"
        iyz="0.000167026705837287"
        izz="0.000118948620340714" />
    </inertial>
    <visual>
      <origin
        xyz="0 0 0"
        rpy="0 0 0" />
      <geometry>
        <mesh
          filename="package://delta/meshes/forarm4.STL" />
      </geometry>
      <material
        name="">
        <color
          rgba="0.792156862745098 0.819607843137255 0.933333333333333 1" />
      </material>
    </visual>
    <collision>
      <origin
        xyz="0 0 0"
        rpy="0 0 0" />
      <geometry>
        <mesh
          filename="package://delta/meshes/forarm4.STL" />
      </geometry>
    </collision>
  </link>
  <joint
    name="forarm4_con12"
    type="continuous">
    <origin
      xyz="0.0289999692661698 4.22202816073858E-05 0"
      rpy="0 0 0" />
    <parent
      link="con12" />
    <child
      link="forarm4" />
    <axis
      xyz="0 1 0" />
  </joint>
  <link
    name="Biceb3">
    <inertial>
      <origin
        xyz="-0.00049566363650777 0.140948034908515 6.29918339711821E-12"
        rpy="0 0 0" />
      <mass
        value="0.0192073729616364" />
      <inertia
        ixx="0.000166344843633273"
        ixy="6.62076203416362E-19"
        ixz="-5.661894768993E-21"
        iyy="1.42950996298078E-06"
        iyz="3.65653535417841E-19"
        izz="0.0001649281385856" />
    </inertial>
    <visual>
      <origin
        xyz="0 0 0"
        rpy="0 0 0" />
      <geometry>
        <mesh
          filename="package://delta/meshes/Biceb3.STL" />
      </geometry>
      <material
        name="">
        <color
          rgba="0.792156862745098 0.819607843137255 0.933333333333333 1" />
      </material>
    </visual>
    <collision>
      <origin
        xyz="0 0 0"
        rpy="0 0 0" />
      <geometry>
        <mesh
          filename="package://delta/meshes/Biceb3.STL" />
      </geometry>
    </collision>
  </link>
  <joint
    name="biceb_base3"
    type="continuous">
    <origin
      xyz="0.160831805716202 0.000595252407950997 -0.033973265636227"
      rpy="2.61490408337707 0 1.56829632419074" />
    <parent
      link="base_link" />
    <child
      link="Biceb3" />
    <axis
      xyz="1 0 0" />
  </joint>
  <link
    name="con13">
    <inertial>
      <origin
        xyz="-8.5043083686287E-14 -9.46864808781811E-11 -1.62825086746921E-10"
        rpy="0 0 0" />
      <mass
        value="0.00746291618045563" />
      <inertia
        ixx="2.35119365324097E-07"
        ixy="2.14430079153028E-10"
        ixz="4.75372243406834E-23"
        iyy="4.75779372735656E-07"
        iyz="9.4426491856887E-24"
        izz="4.75779563794498E-07" />
    </inertial>
    <visual>
      <origin
        xyz="0 0 0"
        rpy="0 0 0" />
      <geometry>
        <mesh
          filename="package://delta/meshes/con13.STL" />
      </geometry>
      <material
        name="">
        <color
          rgba="0.792156862745098 0.819607843137255 0.933333333333333 1" />
      </material>
    </visual>
    <collision>
      <origin
        xyz="0 0 0"
        rpy="0 0 0" />
      <geometry>
        <mesh
          filename="package://delta/meshes/con13.STL" />
      </geometry>
    </collision>
  </link>
  <joint
    name="biceb_con13"
    type="continuous">
    <origin
      xyz="-0.000495663636507992 0.289999999999974 0"
      rpy="-2.61490425587017 0.000447885728932077 -0.00077025491561851" />
    <parent
      link="Biceb3" />
    <child
      link="con13" />
    <axis
      xyz="0.999999603052915 -0.000891007301572988 0" />
  </joint>
  <link
    name="forarm5">
    <inertial>
      <origin
        xyz="2.54045823504523E-05 0.14831197052904 -0.21020505749921"
        rpy="0 0 0" />
      <mass
        value="0.0144304093208629" />
      <inertia
        ixx="0.000353664776789159"
        ixy="-1.91943230751328E-08"
        ixz="2.91864673212062E-08"
        iyy="0.000236136299280177"
        iyz="0.000166548936792648"
        izz="0.000117593780480283" />
    </inertial>
    <visual>
      <origin
        xyz="0 0 0"
        rpy="0 0 0" />
      <geometry>
        <mesh
          filename="package://delta/meshes/forarm5.STL" />
      </geometry>
      <material
        name="">
        <color
          rgba="0.752941176470588 0.752941176470588 0.752941176470588 1" />
      </material>
    </visual>
    <collision>
      <origin
        xyz="0 0 0"
        rpy="0 0 0" />
      <geometry>
        <mesh
          filename="package://delta/meshes/forarm5.STL" />
      </geometry>
    </collision>
  </link>
  <joint
    name="forarm5_con13"
    type="continuous">
    <origin
      xyz="-0.0289999884886679 2.5839211660994E-05 0"
      rpy="0 0 0" />
    <parent
      link="con13" />
    <child
      link="forarm5" />
    <axis
      xyz="0 1 0" />
  </joint>
  <link
    name="forarm6">
    <inertial>
      <origin
        xyz="2.54023930122971E-05 0.148311967474546 -0.210205054603508"
        rpy="0 0 0" />
      <mass
        value="0.0144304095682966" />
      <inertia
        ixx="0.000353664825395716"
        ixy="-2.06501371555305E-08"
        ixz="2.81594225114868E-08"
        iyy="0.000236136267343819"
        iyz="0.000166548913747927"
        izz="0.000117593763848959" />
    </inertial>
    <visual>
      <origin
        xyz="0 0 0"
        rpy="0 0 0" />
      <geometry>
        <mesh
          filename="package://delta/meshes/forarm6.STL" />
      </geometry>
      <material
        name="">
        <color
          rgba="0.792156862745098 0.819607843137255 0.933333333333333 1" />
      </material>
    </visual>
    <collision>
      <origin
        xyz="0 0 0"
        rpy="0 0 0" />
      <geometry>
        <mesh
          filename="package://delta/meshes/forarm6.STL" />
      </geometry>
    </collision>
  </link>
  <joint
    name="forarm6_con13"
    type="continuous">
    <origin
      xyz="0.0289999884886464 -2.5839211899692E-05 0"
      rpy="0 0 0" />
    <parent
      link="con13" />
    <child
      link="forarm6" />
    <axis
      xyz="0 1 0" />
  </joint>
</robot>